Watching for file changes with StatReloader
Internal Server Error: /data/
Traceback (most recent call last):
  File "C:\Users\JSANTIAGO\Projects\dashboard_project\venv\lib\site-packages\django\db\backends\utils.py", line 87, in _execute
    return self.cursor.execute(sql)
  File "C:\Users\JSANTIAGO\Projects\dashboard_project\venv\lib\site-packages\django\db\backends\sqlite3\base.py", line 324, in execute
    return super().execute(query)
sqlite3.OperationalError: near "10": syntax error

The above exception was the direct cause of the following exception:

Traceback (most recent call last):
  File "C:\Users\JSANTIAGO\Projects\dashboard_project\venv\lib\site-packages\django\core\handlers\exception.py", line 55, in inner
    response = get_response(request)
  File "C:\Users\JSANTIAGO\Projects\dashboard_project\venv\lib\site-packages\django\core\handlers\base.py", line 197, in _get_response
    response = wrapped_callback(request, *callback_args, **callback_kwargs)
  File "C:\Users\JSANTIAGO\Projects\dashboard_project\live_dashboard\dashboard\views.py", line 24, in sample_data
    cursor.execute("SELECT TOP 10 id, name, value FROM YourTable")
  File "C:\Users\JSANTIAGO\Projects\dashboard_project\venv\lib\site-packages\django\db\backends\utils.py", line 102, in execute
    return super().execute(sql, params)
  File "C:\Users\JSANTIAGO\Projects\dashboard_project\venv\lib\site-packages\django\db\backends\utils.py", line 67, in execute
    return self._execute_with_wrappers(
  File "C:\Users\JSANTIAGO\Projects\dashboard_project\venv\lib\site-packages\django\db\backends\utils.py", line 80, in _execute_with_wrappers
    return executor(sql, params, many, context)
  File "C:\Users\JSANTIAGO\Projects\dashboard_project\venv\lib\site-packages\django\db\backends\utils.py", line 89, in _execute
    return self.cursor.execute(sql, params)
  File "C:\Users\JSANTIAGO\Projects\dashboard_project\venv\lib\site-packages\django\db\utils.py", line 91, in __exit__
    raise dj_exc_value.with_traceback(traceback) from exc_value
  File "C:\Users\JSANTIAGO\Projects\dashboard_project\venv\lib\site-packages\django\db\backends\utils.py", line 87, in _execute
    return self.cursor.execute(sql)
  File "C:\Users\JSANTIAGO\Projects\dashboard_project\venv\lib\site-packages\django\db\backends\sqlite3\base.py", line 324, in execute
    return super().execute(query)
django.db.utils.OperationalError: near "10": syntax error
[17/Jun/2025 14:20:11] "GET /data/ HTTP/1.1" 500 113959
[17/Jun/2025 14:20:25] "GET / HTTP/1.1" 200 983
Internal Server Error: /data/
Traceback (most recent call last):
  File "C:\Users\JSANTIAGO\Projects\dashboard_project\venv\lib\site-packages\django\db\backends\utils.py", line 87, in _execute
    return self.cursor.execute(sql)
  File "C:\Users\JSANTIAGO\Projects\dashboard_project\venv\lib\site-packages\django\db\backends\sqlite3\base.py", line 324, in execute
    return super().execute(query)
sqlite3.OperationalError: near "10": syntax error

The above exception was the direct cause of the following exception:

Traceback (most recent call last):
  File "C:\Users\JSANTIAGO\Projects\dashboard_project\venv\lib\site-packages\django\core\handlers\exception.py", line 55, in inner
    response = get_response(request)
  File "C:\Users\JSANTIAGO\Projects\dashboard_project\venv\lib\site-packages\django\core\handlers\base.py", line 197, in _get_response
    response = wrapped_callback(request, *callback_args, **callback_kwargs)
  File "C:\Users\JSANTIAGO\Projects\dashboard_project\live_dashboard\dashboard\views.py", line 24, in sample_data
    cursor.execute("SELECT TOP 10 id, name, value FROM YourTable")
  File "C:\Users\JSANTIAGO\Projects\dashboard_project\venv\lib\site-packages\django\db\backends\utils.py", line 102, in execute
    return super().execute(sql, params)
  File "C:\Users\JSANTIAGO\Projects\dashboard_project\venv\lib\site-packages\django\db\backends\utils.py", line 67, in execute
    return self._execute_with_wrappers(
  File "C:\Users\JSANTIAGO\Projects\dashboard_project\venv\lib\site-packages\django\db\backends\utils.py", line 80, in _execute_with_wrappers
    return executor(sql, params, many, context)
  File "C:\Users\JSANTIAGO\Projects\dashboard_project\venv\lib\site-packages\django\db\backends\utils.py", line 89, in _execute
    return self.cursor.execute(sql, params)
  File "C:\Users\JSANTIAGO\Projects\dashboard_project\venv\lib\site-packages\django\db\utils.py", line 91, in __exit__
    raise dj_exc_value.with_traceback(traceback) from exc_value
  File "C:\Users\JSANTIAGO\Projects\dashboard_project\venv\lib\site-packages\django\db\backends\utils.py", line 87, in _execute
    return self.cursor.execute(sql)
  File "C:\Users\JSANTIAGO\Projects\dashboard_project\venv\lib\site-packages\django\db\backends\sqlite3\base.py", line 324, in execute
    return super().execute(query)
django.db.utils.OperationalError: near "10": syntax error
[17/Jun/2025 14:20:25] "GET /data/ HTTP/1.1" 500 113959
Not Found: /favicon.ico
[17/Jun/2025 14:20:25] "GET /favicon.ico HTTP/1.1" 404 2596
Internal Server Error: /data/
Traceback (most recent call last):
  File "C:\Users\JSANTIAGO\Projects\dashboard_project\venv\lib\site-packages\django\db\backends\utils.py", line 87, in _execute
    return self.cursor.execute(sql)
  File "C:\Users\JSANTIAGO\Projects\dashboard_project\venv\lib\site-packages\django\db\backends\sqlite3\base.py", line 324, in execute
    return super().execute(query)
sqlite3.OperationalError: near "10": syntax error

The above exception was the direct cause of the following exception:

Traceback (most recent call last):
  File "C:\Users\JSANTIAGO\Projects\dashboard_project\venv\lib\site-packages\django\core\handlers\exception.py", line 55, in inner
    response = get_response(request)
  File "C:\Users\JSANTIAGO\Projects\dashboard_project\venv\lib\site-packages\django\core\handlers\base.py", line 197, in _get_response
    response = wrapped_callback(request, *callback_args, **callback_kwargs)
  File "C:\Users\JSANTIAGO\Projects\dashboard_project\live_dashboard\dashboard\views.py", line 24, in sample_data
    cursor.execute("SELECT TOP 10 id, name, value FROM YourTable")
  File "C:\Users\JSANTIAGO\Projects\dashboard_project\venv\lib\site-packages\django\db\backends\utils.py", line 102, in execute
    return super().execute(sql, params)
  File "C:\Users\JSANTIAGO\Projects\dashboard_project\venv\lib\site-packages\django\db\backends\utils.py", line 67, in execute
    return self._execute_with_wrappers(
  File "C:\Users\JSANTIAGO\Projects\dashboard_project\venv\lib\site-packages\django\db\backends\utils.py", line 80, in _execute_with_wrappers
    return executor(sql, params, many, context)
  File "C:\Users\JSANTIAGO\Projects\dashboard_project\venv\lib\site-packages\django\db\backends\utils.py", line 89, in _execute
    return self.cursor.execute(sql, params)
  File "C:\Users\JSANTIAGO\Projects\dashboard_project\venv\lib\site-packages\django\db\utils.py", line 91, in __exit__
    raise dj_exc_value.with_traceback(traceback) from exc_value
  File "C:\Users\JSANTIAGO\Projects\dashboard_project\venv\lib\site-packages\django\db\backends\utils.py", line 87, in _execute
    return self.cursor.execute(sql)
  File "C:\Users\JSANTIAGO\Projects\dashboard_project\venv\lib\site-packages\django\db\backends\sqlite3\base.py", line 324, in execute
    return super().execute(query)
django.db.utils.OperationalError: near "10": syntax error
[17/Jun/2025 14:21:25] "GET /data/ HTTP/1.1" 500 113959
Internal Server Error: /data/
Traceback (most recent call last):
  File "C:\Users\JSANTIAGO\Projects\dashboard_project\venv\lib\site-packages\django\db\backends\utils.py", line 87, in _execute
    return self.cursor.execute(sql)
  File "C:\Users\JSANTIAGO\Projects\dashboard_project\venv\lib\site-packages\django\db\backends\sqlite3\base.py", line 324, in execute
    return super().execute(query)
sqlite3.OperationalError: near "10": syntax error

The above exception was the direct cause of the following exception:

Traceback (most recent call last):
  File "C:\Users\JSANTIAGO\Projects\dashboard_project\venv\lib\site-packages\django\core\handlers\exception.py", line 55, in inner
    response = get_response(request)
  File "C:\Users\JSANTIAGO\Projects\dashboard_project\venv\lib\site-packages\django\core\handlers\base.py", line 197, in _get_response
    response = wrapped_callback(request, *callback_args, **callback_kwargs)
  File "C:\Users\JSANTIAGO\Projects\dashboard_project\live_dashboard\dashboard\views.py", line 24, in sample_data
    cursor.execute("SELECT TOP 10 id, name, value FROM YourTable")
  File "C:\Users\JSANTIAGO\Projects\dashboard_project\venv\lib\site-packages\django\db\backends\utils.py", line 102, in execute
    return super().execute(sql, params)
  File "C:\Users\JSANTIAGO\Projects\dashboard_project\venv\lib\site-packages\django\db\backends\utils.py", line 67, in execute
    return self._execute_with_wrappers(
  File "C:\Users\JSANTIAGO\Projects\dashboard_project\venv\lib\site-packages\django\db\backends\utils.py", line 80, in _execute_with_wrappers
    return executor(sql, params, many, context)
  File "C:\Users\JSANTIAGO\Projects\dashboard_project\venv\lib\site-packages\django\db\backends\utils.py", line 89, in _execute
    return self.cursor.execute(sql, params)
  File "C:\Users\JSANTIAGO\Projects\dashboard_project\venv\lib\site-packages\django\db\utils.py", line 91, in __exit__
    raise dj_exc_value.with_traceback(traceback) from exc_value
  File "C:\Users\JSANTIAGO\Projects\dashboard_project\venv\lib\site-packages\django\db\backends\utils.py", line 87, in _execute
    return self.cursor.execute(sql)
  File "C:\Users\JSANTIAGO\Projects\dashboard_project\venv\lib\site-packages\django\db\backends\sqlite3\base.py", line 324, in execute
    return super().execute(query)
django.db.utils.OperationalError: near "10": syntax error
[17/Jun/2025 14:22:25] "GET /data/ HTTP/1.1" 500 113959
Internal Server Error: /data/
Traceback (most recent call last):
  File "C:\Users\JSANTIAGO\Projects\dashboard_project\venv\lib\site-packages\django\db\backends\utils.py", line 87, in _execute
    return self.cursor.execute(sql)
  File "C:\Users\JSANTIAGO\Projects\dashboard_project\venv\lib\site-packages\django\db\backends\sqlite3\base.py", line 324, in execute
    return super().execute(query)
sqlite3.OperationalError: near "10": syntax error

The above exception was the direct cause of the following exception:

Traceback (most recent call last):
  File "C:\Users\JSANTIAGO\Projects\dashboard_project\venv\lib\site-packages\django\core\handlers\exception.py", line 55, in inner
    response = get_response(request)
  File "C:\Users\JSANTIAGO\Projects\dashboard_project\venv\lib\site-packages\django\core\handlers\base.py", line 197, in _get_response
    response = wrapped_callback(request, *callback_args, **callback_kwargs)
  File "C:\Users\JSANTIAGO\Projects\dashboard_project\live_dashboard\dashboard\views.py", line 24, in sample_data
    cursor.execute("SELECT TOP 10 id, name, value FROM YourTable")
  File "C:\Users\JSANTIAGO\Projects\dashboard_project\venv\lib\site-packages\django\db\backends\utils.py", line 102, in execute
    return super().execute(sql, params)
  File "C:\Users\JSANTIAGO\Projects\dashboard_project\venv\lib\site-packages\django\db\backends\utils.py", line 67, in execute
    return self._execute_with_wrappers(
  File "C:\Users\JSANTIAGO\Projects\dashboard_project\venv\lib\site-packages\django\db\backends\utils.py", line 80, in _execute_with_wrappers
    return executor(sql, params, many, context)
  File "C:\Users\JSANTIAGO\Projects\dashboard_project\venv\lib\site-packages\django\db\backends\utils.py", line 89, in _execute
    return self.cursor.execute(sql, params)
  File "C:\Users\JSANTIAGO\Projects\dashboard_project\venv\lib\site-packages\django\db\utils.py", line 91, in __exit__
    raise dj_exc_value.with_traceback(traceback) from exc_value
  File "C:\Users\JSANTIAGO\Projects\dashboard_project\venv\lib\site-packages\django\db\backends\utils.py", line 87, in _execute
    return self.cursor.execute(sql)
  File "C:\Users\JSANTIAGO\Projects\dashboard_project\venv\lib\site-packages\django\db\backends\sqlite3\base.py", line 324, in execute
    return super().execute(query)
django.db.utils.OperationalError: near "10": syntax error
[17/Jun/2025 14:22:59] "GET /data/ HTTP/1.1" 500 114219
C:\Users\JSANTIAGO\Projects\dashboard_project\live_dashboard\dashboard\views.py changed, reloading.
Performing system checks...

System check identified no issues (0 silenced).
June 17, 2025 - 14:19:18
Django version 4.2.23, using settings 'live_dashboard.settings'
Starting development server at http://127.0.0.1:8000/
Quit the server with CTRL-BREAK.

Watching for file changes with StatReloader
Internal Server Error: /data/
Traceback (most recent call last):
  File "C:\Users\JSANTIAGO\Projects\dashboard_project\venv\lib\site-packages\django\db\backends\utils.py", line 87, in _execute
    return self.cursor.execute(sql)
  File "C:\Users\JSANTIAGO\Projects\dashboard_project\venv\lib\site-packages\django\db\backends\sqlite3\base.py", line 324, in execute
    return super().execute(query)
sqlite3.OperationalError: no such table: YourTable

The above exception was the direct cause of the following exception:

Traceback (most recent call last):
  File "C:\Users\JSANTIAGO\Projects\dashboard_project\venv\lib\site-packages\django\core\handlers\exception.py", line 55, in inner
    response = get_response(request)
  File "C:\Users\JSANTIAGO\Projects\dashboard_project\venv\lib\site-packages\django\core\handlers\base.py", line 197, in _get_response
    response = wrapped_callback(request, *callback_args, **callback_kwargs)
  File "C:\Users\JSANTIAGO\Projects\dashboard_project\live_dashboard\dashboard\views.py", line 27, in sample_data
    cursor.execute("SELECT id, name, value FROM YourTable LIMIT 10")
  File "C:\Users\JSANTIAGO\Projects\dashboard_project\venv\lib\site-packages\django\db\backends\utils.py", line 102, in execute
    return super().execute(sql, params)
  File "C:\Users\JSANTIAGO\Projects\dashboard_project\venv\lib\site-packages\django\db\backends\utils.py", line 67, in execute
    return self._execute_with_wrappers(
  File "C:\Users\JSANTIAGO\Projects\dashboard_project\venv\lib\site-packages\django\db\backends\utils.py", line 80, in _execute_with_wrappers
    return executor(sql, params, many, context)
  File "C:\Users\JSANTIAGO\Projects\dashboard_project\venv\lib\site-packages\django\db\backends\utils.py", line 89, in _execute
    return self.cursor.execute(sql, params)
  File "C:\Users\JSANTIAGO\Projects\dashboard_project\venv\lib\site-packages\django\db\utils.py", line 91, in __exit__
    raise dj_exc_value.with_traceback(traceback) from exc_value
  File "C:\Users\JSANTIAGO\Projects\dashboard_project\venv\lib\site-packages\django\db\backends\utils.py", line 87, in _execute
    return self.cursor.execute(sql)
  File "C:\Users\JSANTIAGO\Projects\dashboard_project\venv\lib\site-packages\django\db\backends\sqlite3\base.py", line 324, in execute
    return super().execute(query)
django.db.utils.OperationalError: no such table: YourTable
[17/Jun/2025 14:26:14] "GET /data/ HTTP/1.1" 500 114431
Internal Server Error: /data/
Traceback (most recent call last):
  File "C:\Users\JSANTIAGO\Projects\dashboard_project\venv\lib\site-packages\django\db\backends\utils.py", line 87, in _execute
    return self.cursor.execute(sql)
  File "C:\Users\JSANTIAGO\Projects\dashboard_project\venv\lib\site-packages\django\db\backends\sqlite3\base.py", line 324, in execute
    return super().execute(query)
sqlite3.OperationalError: no such table: YourTable

The above exception was the direct cause of the following exception:

Traceback (most recent call last):
  File "C:\Users\JSANTIAGO\Projects\dashboard_project\venv\lib\site-packages\django\core\handlers\exception.py", line 55, in inner
    response = get_response(request)
  File "C:\Users\JSANTIAGO\Projects\dashboard_project\venv\lib\site-packages\django\core\handlers\base.py", line 197, in _get_response
    response = wrapped_callback(request, *callback_args, **callback_kwargs)
  File "C:\Users\JSANTIAGO\Projects\dashboard_project\live_dashboard\dashboard\views.py", line 27, in sample_data
    cursor.execute("SELECT id, name, value FROM YourTable LIMIT 10")
  File "C:\Users\JSANTIAGO\Projects\dashboard_project\venv\lib\site-packages\django\db\backends\utils.py", line 102, in execute
    return super().execute(sql, params)
  File "C:\Users\JSANTIAGO\Projects\dashboard_project\venv\lib\site-packages\django\db\backends\utils.py", line 67, in execute
    return self._execute_with_wrappers(
  File "C:\Users\JSANTIAGO\Projects\dashboard_project\venv\lib\site-packages\django\db\backends\utils.py", line 80, in _execute_with_wrappers
    return executor(sql, params, many, context)
  File "C:\Users\JSANTIAGO\Projects\dashboard_project\venv\lib\site-packages\django\db\backends\utils.py", line 89, in _execute
    return self.cursor.execute(sql, params)
  File "C:\Users\JSANTIAGO\Projects\dashboard_project\venv\lib\site-packages\django\db\utils.py", line 91, in __exit__
    raise dj_exc_value.with_traceback(traceback) from exc_value
  File "C:\Users\JSANTIAGO\Projects\dashboard_project\venv\lib\site-packages\django\db\backends\utils.py", line 87, in _execute
    return self.cursor.execute(sql)
  File "C:\Users\JSANTIAGO\Projects\dashboard_project\venv\lib\site-packages\django\db\backends\sqlite3\base.py", line 324, in execute
    return super().execute(query)
django.db.utils.OperationalError: no such table: YourTable
[17/Jun/2025 14:26:17] "GET /data/ HTTP/1.1" 500 114431
[17/Jun/2025 14:26:43] "GET /debug/ HTTP/1.1" 200 188
Internal Server Error: /data/
Traceback (most recent call last):
  File "C:\Users\JSANTIAGO\Projects\dashboard_project\venv\lib\site-packages\django\db\backends\utils.py", line 87, in _execute
    return self.cursor.execute(sql)
  File "C:\Users\JSANTIAGO\Projects\dashboard_project\venv\lib\site-packages\django\db\backends\sqlite3\base.py", line 324, in execute
    return super().execute(query)
sqlite3.OperationalError: no such table: YourTable

The above exception was the direct cause of the following exception:

Traceback (most recent call last):
  File "C:\Users\JSANTIAGO\Projects\dashboard_project\venv\lib\site-packages\django\core\handlers\exception.py", line 55, in inner
    response = get_response(request)
  File "C:\Users\JSANTIAGO\Projects\dashboard_project\venv\lib\site-packages\django\core\handlers\base.py", line 197, in _get_response
    response = wrapped_callback(request, *callback_args, **callback_kwargs)
  File "C:\Users\JSANTIAGO\Projects\dashboard_project\live_dashboard\dashboard\views.py", line 27, in sample_data
    cursor.execute("SELECT id, name, value FROM YourTable LIMIT 10")
  File "C:\Users\JSANTIAGO\Projects\dashboard_project\venv\lib\site-packages\django\db\backends\utils.py", line 102, in execute
    return super().execute(sql, params)
  File "C:\Users\JSANTIAGO\Projects\dashboard_project\venv\lib\site-packages\django\db\backends\utils.py", line 67, in execute
    return self._execute_with_wrappers(
  File "C:\Users\JSANTIAGO\Projects\dashboard_project\venv\lib\site-packages\django\db\backends\utils.py", line 80, in _execute_with_wrappers
    return executor(sql, params, many, context)
  File "C:\Users\JSANTIAGO\Projects\dashboard_project\venv\lib\site-packages\django\db\backends\utils.py", line 89, in _execute
    return self.cursor.execute(sql, params)
  File "C:\Users\JSANTIAGO\Projects\dashboard_project\venv\lib\site-packages\django\db\utils.py", line 91, in __exit__
    raise dj_exc_value.with_traceback(traceback) from exc_value
  File "C:\Users\JSANTIAGO\Projects\dashboard_project\venv\lib\site-packages\django\db\backends\utils.py", line 87, in _execute
    return self.cursor.execute(sql)
  File "C:\Users\JSANTIAGO\Projects\dashboard_project\venv\lib\site-packages\django\db\backends\sqlite3\base.py", line 324, in execute
    return super().execute(query)
django.db.utils.OperationalError: no such table: YourTable
[17/Jun/2025 14:33:58] "GET /data/ HTTP/1.1" 500 114294
C:\Users\JSANTIAGO\Projects\dashboard_project\live_dashboard\dashboard\views.py changed, reloading.
Performing system checks...

System check identified no issues (0 silenced).
June 17, 2025 - 14:25:55
Django version 4.2.23, using settings 'live_dashboard.settings'
Starting development server at http://127.0.0.1:8000/
Quit the server with CTRL-BREAK.

Watching for file changes with StatReloader
[17/Jun/2025 17:16:02] "GET / HTTP/1.1" 200 983
Internal Server Error: /data/
Traceback (most recent call last):
  File "C:\Users\JSANTIAGO\Projects\dashboard_project\venv\lib\site-packages\django\db\backends\utils.py", line 87, in _execute
    return self.cursor.execute(sql)
  File "C:\Users\JSANTIAGO\Projects\dashboard_project\venv\lib\site-packages\django\db\backends\sqlite3\base.py", line 324, in execute
    return super().execute(query)
sqlite3.OperationalError: no such table: YourTable

The above exception was the direct cause of the following exception:

Traceback (most recent call last):
  File "C:\Users\JSANTIAGO\Projects\dashboard_project\venv\lib\site-packages\django\core\handlers\exception.py", line 55, in inner
    response = get_response(request)
  File "C:\Users\JSANTIAGO\Projects\dashboard_project\venv\lib\site-packages\django\core\handlers\base.py", line 197, in _get_response
    response = wrapped_callback(request, *callback_args, **callback_kwargs)
  File "C:\Users\JSANTIAGO\Projects\dashboard_project\live_dashboard\dashboard\views.py", line 33, in sample_data
    cursor.execute("SELECT id, name, value FROM YourTable LIMIT 10")
  File "C:\Users\JSANTIAGO\Projects\dashboard_project\venv\lib\site-packages\django\db\backends\utils.py", line 102, in execute
    return super().execute(sql, params)
  File "C:\Users\JSANTIAGO\Projects\dashboard_project\venv\lib\site-packages\django\db\backends\utils.py", line 67, in execute
    return self._execute_with_wrappers(
  File "C:\Users\JSANTIAGO\Projects\dashboard_project\venv\lib\site-packages\django\db\backends\utils.py", line 80, in _execute_with_wrappers
    return executor(sql, params, many, context)
  File "C:\Users\JSANTIAGO\Projects\dashboard_project\venv\lib\site-packages\django\db\backends\utils.py", line 89, in _execute
    return self.cursor.execute(sql, params)
  File "C:\Users\JSANTIAGO\Projects\dashboard_project\venv\lib\site-packages\django\db\utils.py", line 91, in __exit__
    raise dj_exc_value.with_traceback(traceback) from exc_value
  File "C:\Users\JSANTIAGO\Projects\dashboard_project\venv\lib\site-packages\django\db\backends\utils.py", line 87, in _execute
    return self.cursor.execute(sql)
  File "C:\Users\JSANTIAGO\Projects\dashboard_project\venv\lib\site-packages\django\db\backends\sqlite3\base.py", line 324, in execute
    return super().execute(query)
django.db.utils.OperationalError: no such table: YourTable
[17/Jun/2025 17:16:03] "GET /data/ HTTP/1.1" 500 114034
Internal Server Error: /data/
Traceback (most recent call last):
  File "C:\Users\JSANTIAGO\Projects\dashboard_project\venv\lib\site-packages\django\db\backends\utils.py", line 87, in _execute
    return self.cursor.execute(sql)
  File "C:\Users\JSANTIAGO\Projects\dashboard_project\venv\lib\site-packages\django\db\backends\sqlite3\base.py", line 324, in execute
    return super().execute(query)
sqlite3.OperationalError: no such table: YourTable

The above exception was the direct cause of the following exception:

Traceback (most recent call last):
  File "C:\Users\JSANTIAGO\Projects\dashboard_project\venv\lib\site-packages\django\core\handlers\exception.py", line 55, in inner
    response = get_response(request)
  File "C:\Users\JSANTIAGO\Projects\dashboard_project\venv\lib\site-packages\django\core\handlers\base.py", line 197, in _get_response
    response = wrapped_callback(request, *callback_args, **callback_kwargs)
  File "C:\Users\JSANTIAGO\Projects\dashboard_project\live_dashboard\dashboard\views.py", line 33, in sample_data
    cursor.execute("SELECT id, name, value FROM YourTable LIMIT 10")
  File "C:\Users\JSANTIAGO\Projects\dashboard_project\venv\lib\site-packages\django\db\backends\utils.py", line 102, in execute
    return super().execute(sql, params)
  File "C:\Users\JSANTIAGO\Projects\dashboard_project\venv\lib\site-packages\django\db\backends\utils.py", line 67, in execute
    return self._execute_with_wrappers(
  File "C:\Users\JSANTIAGO\Projects\dashboard_project\venv\lib\site-packages\django\db\backends\utils.py", line 80, in _execute_with_wrappers
    return executor(sql, params, many, context)
  File "C:\Users\JSANTIAGO\Projects\dashboard_project\venv\lib\site-packages\django\db\backends\utils.py", line 89, in _execute
    return self.cursor.execute(sql, params)
  File "C:\Users\JSANTIAGO\Projects\dashboard_project\venv\lib\site-packages\django\db\utils.py", line 91, in __exit__
    raise dj_exc_value.with_traceback(traceback) from exc_value
  File "C:\Users\JSANTIAGO\Projects\dashboard_project\venv\lib\site-packages\django\db\backends\utils.py", line 87, in _execute
    return self.cursor.execute(sql)
  File "C:\Users\JSANTIAGO\Projects\dashboard_project\venv\lib\site-packages\django\db\backends\sqlite3\base.py", line 324, in execute
    return super().execute(query)
django.db.utils.OperationalError: no such table: YourTable
[17/Jun/2025 17:16:16] "GET /data/ HTTP/1.1" 500 114294
Traceback (most recent call last):
  File "manage.py", line 11, in main
    from django.core.management import execute_from_command_line
ModuleNotFoundError: No module named 'django'

The above exception was the direct cause of the following exception:

Traceback (most recent call last):
  File "manage.py", line 22, in <module>
    main()
  File "manage.py", line 13, in main
    raise ImportError(
ImportError: Couldn't import Django. Are you sure it's installed and available on your PYTHONPATH environment variable? Did you forget to activate a virtual environment?
Traceback (most recent call last):
  File "manage.py", line 11, in main
    from django.core.management import execute_from_command_line
ModuleNotFoundError: No module named 'django'

The above exception was the direct cause of the following exception:

Traceback (most recent call last):
  File "manage.py", line 22, in <module>
    main()
  File "manage.py", line 13, in main
    raise ImportError(
ImportError: Couldn't import Django. Are you sure it's installed and available on your PYTHONPATH environment variable? Did you forget to activate a virtual environment?
Traceback (most recent call last):
  File "manage.py", line 11, in main
    from django.core.management import execute_from_command_line
ModuleNotFoundError: No module named 'django'

The above exception was the direct cause of the following exception:

Traceback (most recent call last):
  File "manage.py", line 22, in <module>
    main()
  File "manage.py", line 13, in main
    raise ImportError(
ImportError: Couldn't import Django. Are you sure it's installed and available on your PYTHONPATH environment variable? Did you forget to activate a virtual environment?
Watching for file changes with StatReloader
[18/Jun/2025 13:37:01] "GET / HTTP/1.1" 200 983
[18/Jun/2025 13:37:01] "GET /data/ HTTP/1.1" 200 118
Not Found: /favicon.ico
[18/Jun/2025 13:37:01] "GET /favicon.ico HTTP/1.1" 404 2596
[18/Jun/2025 13:38:01] "GET /data/ HTTP/1.1" 200 118
[18/Jun/2025 13:39:01] "GET /data/ HTTP/1.1" 200 118
[18/Jun/2025 13:40:01] "GET /data/ HTTP/1.1" 200 118
[18/Jun/2025 13:41:01] "GET /data/ HTTP/1.1" 200 118
[18/Jun/2025 13:42:01] "GET /data/ HTTP/1.1" 200 118
[18/Jun/2025 13:43:01] "GET /data/ HTTP/1.1" 200 118
[18/Jun/2025 13:44:01] "GET /data/ HTTP/1.1" 200 118
[18/Jun/2025 13:45:02] "GET /data/ HTTP/1.1" 200 118
[18/Jun/2025 13:46:03] "GET /data/ HTTP/1.1" 200 118
[18/Jun/2025 13:47:04] "GET /data/ HTTP/1.1" 200 118
[18/Jun/2025 13:48:05] "GET /data/ HTTP/1.1" 200 118
[18/Jun/2025 13:49:06] "GET /data/ HTTP/1.1" 200 118
[18/Jun/2025 13:50:07] "GET /data/ HTTP/1.1" 200 118
[18/Jun/2025 13:51:08] "GET /data/ HTTP/1.1" 200 118
[18/Jun/2025 13:52:09] "GET /data/ HTTP/1.1" 200 118
[18/Jun/2025 13:53:10] "GET /data/ HTTP/1.1" 200 118
[18/Jun/2025 13:54:10] "GET /data/ HTTP/1.1" 200 118
[18/Jun/2025 13:55:10] "GET /data/ HTTP/1.1" 200 118
[18/Jun/2025 13:56:10] "GET /data/ HTTP/1.1" 200 118
[18/Jun/2025 13:57:10] "GET /data/ HTTP/1.1" 200 118
[18/Jun/2025 13:58:10] "GET /data/ HTTP/1.1" 200 118
[18/Jun/2025 13:59:10] "GET /data/ HTTP/1.1" 200 118
[18/Jun/2025 14:00:10] "GET /data/ HTTP/1.1" 200 118
[18/Jun/2025 14:01:10] "GET /data/ HTTP/1.1" 200 118
[18/Jun/2025 14:02:10] "GET /data/ HTTP/1.1" 200 118
[18/Jun/2025 14:03:10] "GET /data/ HTTP/1.1" 200 118
[18/Jun/2025 14:04:10] "GET /data/ HTTP/1.1" 200 118
[18/Jun/2025 14:05:10] "GET /data/ HTTP/1.1" 200 118
[18/Jun/2025 14:05:34] "GET / HTTP/1.1" 200 983
[18/Jun/2025 14:05:34] "GET /data/ HTTP/1.1" 200 118
[18/Jun/2025 14:05:40] "GET /data/ HTTP/1.1" 200 118
C:\Users\JSANTIAGO\Projects\dashboard_project\live_dashboard\dashboard\views.py changed, reloading.
Performing system checks...

System check identified no issues (0 silenced).
June 18, 2025 - 13:37:00
Django version 4.2.23, using settings 'live_dashboard.settings'
Starting development server at http://127.0.0.1:8000/
Quit the server with CTRL-BREAK.

Watching for file changes with StatReloader
C:\Users\JSANTIAGO\Projects\dashboard_project\live_dashboard\dashboard\views.py changed, reloading.
Performing system checks...

System check identified no issues (0 silenced).
June 18, 2025 - 14:06:35
Django version 4.2.23, using settings 'live_dashboard.settings'
Starting development server at http://127.0.0.1:8000/
Quit the server with CTRL-BREAK.

Watching for file changes with StatReloader
[18/Jun/2025 14:06:42] "GET /data/ HTTP/1.1" 200 208
[18/Jun/2025 14:23:52] "GET /data/ HTTP/1.1" 200 1060
[18/Jun/2025 14:23:59] "GET / HTTP/1.1" 200 983
[18/Jun/2025 14:23:59] "GET /data/ HTTP/1.1" 200 1060
[18/Jun/2025 14:25:00] "GET /data/ HTTP/1.1" 200 1060
[18/Jun/2025 14:25:24] "GET / HTTP/1.1" 200 983
[18/Jun/2025 14:25:25] "GET /data/ HTTP/1.1" 200 1060
[18/Jun/2025 14:25:35] "GET /data/ HTTP/1.1" 200 1060
[18/Jun/2025 14:25:47] "GET /debug/ HTTP/1.1" 200 188
[18/Jun/2025 14:25:59] "GET /data/ HTTP/1.1" 200 1060
C:\Users\JSANTIAGO\Projects\dashboard_project\live_dashboard\dashboard\views.py changed, reloading.
Performing system checks...

System check identified no issues (0 silenced).
June 18, 2025 - 14:06:40
Django version 4.2.23, using settings 'live_dashboard.settings'
Starting development server at http://127.0.0.1:8000/
Quit the server with CTRL-BREAK.

Watching for file changes with StatReloader
[18/Jun/2025 14:27:00] "GET /data/ HTTP/1.1" 200 1060
[18/Jun/2025 14:28:00] "GET /data/ HTTP/1.1" 200 1060
[18/Jun/2025 14:29:00] "GET /data/ HTTP/1.1" 200 1060
[18/Jun/2025 14:30:00] "GET /data/ HTTP/1.1" 200 1060
[18/Jun/2025 14:31:00] "GET /data/ HTTP/1.1" 200 1060
[18/Jun/2025 14:32:01] "GET /data/ HTTP/1.1" 200 1060
[18/Jun/2025 14:33:02] "GET /data/ HTTP/1.1" 200 1060
[18/Jun/2025 14:34:03] "GET /data/ HTTP/1.1" 200 1060
[18/Jun/2025 14:35:00] "GET /data/ HTTP/1.1" 200 1060
[18/Jun/2025 14:36:01] "GET /data/ HTTP/1.1" 200 1060
[18/Jun/2025 14:37:02] "GET /data/ HTTP/1.1" 200 1060
[18/Jun/2025 14:38:03] "GET /data/ HTTP/1.1" 200 1060
[18/Jun/2025 14:39:04] "GET /data/ HTTP/1.1" 200 1060
[18/Jun/2025 14:40:05] "GET /data/ HTTP/1.1" 200 1060
[18/Jun/2025 14:41:06] "GET /data/ HTTP/1.1" 200 1060
[18/Jun/2025 14:42:07] "GET /data/ HTTP/1.1" 200 1060
[18/Jun/2025 14:43:08] "GET /data/ HTTP/1.1" 200 1060
[18/Jun/2025 14:44:09] "GET /data/ HTTP/1.1" 200 1060
[18/Jun/2025 14:45:00] "GET /data/ HTTP/1.1" 200 1060
[18/Jun/2025 14:46:01] "GET /data/ HTTP/1.1" 200 1060
[18/Jun/2025 14:47:02] "GET /data/ HTTP/1.1" 200 1060
[18/Jun/2025 14:48:03] "GET /data/ HTTP/1.1" 200 1060
[18/Jun/2025 14:49:04] "GET /data/ HTTP/1.1" 200 1060
[18/Jun/2025 14:50:05] "GET /data/ HTTP/1.1" 200 1060
[18/Jun/2025 14:51:06] "GET /data/ HTTP/1.1" 200 1060
[18/Jun/2025 14:52:07] "GET /data/ HTTP/1.1" 200 1060
[18/Jun/2025 14:53:08] "GET /data/ HTTP/1.1" 200 1060
[18/Jun/2025 14:54:09] "GET /data/ HTTP/1.1" 200 1060
[18/Jun/2025 14:55:10] "GET /data/ HTTP/1.1" 200 1060
[18/Jun/2025 14:56:10] "GET /data/ HTTP/1.1" 200 1060
[18/Jun/2025 14:57:10] "GET /data/ HTTP/1.1" 200 1060
C:\Users\JSANTIAGO\Projects\dashboard_project\live_dashboard\dashboard\views.py changed, reloading.
Performing system checks...

System check identified no issues (0 silenced).
June 18, 2025 - 14:26:30
Django version 4.2.23, using settings 'live_dashboard.settings'
Starting development server at http://127.0.0.1:8000/
Quit the server with CTRL-BREAK.

Watching for file changes with StatReloader
[18/Jun/2025 14:58:10] "GET /data/ HTTP/1.1" 200 1060
C:\Users\JSANTIAGO\Projects\dashboard_project\live_dashboard\dashboard\urls.py changed, reloading.
Performing system checks...

System check identified no issues (0 silenced).
June 18, 2025 - 14:57:54
Django version 4.2.23, using settings 'live_dashboard.settings'
Starting development server at http://127.0.0.1:8000/
Quit the server with CTRL-BREAK.

Watching for file changes with StatReloader
[18/Jun/2025 14:59:10] "GET /data/ HTTP/1.1" 200 1060
C:\Users\JSANTIAGO\Projects\dashboard_project\live_dashboard\dashboard\views.py changed, reloading.
Performing system checks...

System check identified no issues (0 silenced).
June 18, 2025 - 14:58:47
Django version 4.2.23, using settings 'live_dashboard.settings'
Starting development server at http://127.0.0.1:8000/
Quit the server with CTRL-BREAK.

Watching for file changes with StatReloader
[18/Jun/2025 15:00:10] "GET /data/ HTTP/1.1" 200 1060
[18/Jun/2025 15:01:00] "GET /data/ HTTP/1.1" 200 1060
[18/Jun/2025 15:02:01] "GET /data/ HTTP/1.1" 200 1060
Internal Server Error: /data/gpd/
Traceback (most recent call last):
  File "C:\Users\JSANTIAGO\Projects\dashboard_project\venv\lib\site-packages\django\core\handlers\exception.py", line 55, in inner
    response = get_response(request)
  File "C:\Users\JSANTIAGO\Projects\dashboard_project\venv\lib\site-packages\django\core\handlers\base.py", line 197, in _get_response
    response = wrapped_callback(request, *callback_args, **callback_kwargs)
  File "C:\Users\JSANTIAGO\Projects\dashboard_project\live_dashboard\dashboard\views.py", line 42, in gpd_clients
    return JsonResponse(rows, safe=False)
NameError: name 'rows' is not defined
[18/Jun/2025 15:02:02] "GET /data/gpd/ HTTP/1.1" 500 72594
[18/Jun/2025 15:03:02] "GET /data/ HTTP/1.1" 200 1060
[18/Jun/2025 15:04:03] "GET /data/ HTTP/1.1" 200 1060
[18/Jun/2025 15:05:04] "GET /data/ HTTP/1.1" 200 1060
C:\Users\JSANTIAGO\Projects\dashboard_project\live_dashboard\dashboard\views.py changed, reloading.
Performing system checks...

System check identified no issues (0 silenced).
June 18, 2025 - 14:59:32
Django version 4.2.23, using settings 'live_dashboard.settings'
Starting development server at http://127.0.0.1:8000/
Quit the server with CTRL-BREAK.

Watching for file changes with StatReloader
C:\Users\JSANTIAGO\Projects\dashboard_project\live_dashboard\dashboard\views.py changed, reloading.
Performing system checks...

System check identified no issues (0 silenced).
June 18, 2025 - 15:05:29
Django version 4.2.23, using settings 'live_dashboard.settings'
Starting development server at http://127.0.0.1:8000/
Quit the server with CTRL-BREAK.

Watching for file changes with StatReloader
C:\Users\JSANTIAGO\Projects\dashboard_project\live_dashboard\dashboard\views.py changed, reloading.
Performing system checks...

System check identified no issues (0 silenced).
June 18, 2025 - 15:05:40
Django version 4.2.23, using settings 'live_dashboard.settings'
Starting development server at http://127.0.0.1:8000/
Quit the server with CTRL-BREAK.

Watching for file changes with StatReloader
[18/Jun/2025 15:05:48] "GET /data/gpd/ HTTP/1.1" 200 145
[18/Jun/2025 15:06:05] "GET /data/ HTTP/1.1" 200 1060
[18/Jun/2025 15:07:06] "GET /data/ HTTP/1.1" 200 1060
[18/Jun/2025 15:08:07] "GET /data/ HTTP/1.1" 200 1060
[18/Jun/2025 15:09:08] "GET /data/ HTTP/1.1" 200 1060
C:\Users\JSANTIAGO\Projects\dashboard_project\live_dashboard\dashboard\views.py changed, reloading.
Performing system checks...

System check identified no issues (0 silenced).
June 18, 2025 - 15:05:48
Django version 4.2.23, using settings 'live_dashboard.settings'
Starting development server at http://127.0.0.1:8000/
Quit the server with CTRL-BREAK.

Watching for file changes with StatReloader
[18/Jun/2025 15:10:09] "GET /data/ HTTP/1.1" 200 1060
[18/Jun/2025 15:11:10] "GET /data/ HTTP/1.1" 200 1060
[18/Jun/2025 15:12:10] "GET /data/ HTTP/1.1" 200 1060
[18/Jun/2025 15:13:10] "GET /data/ HTTP/1.1" 200 1060
[18/Jun/2025 15:14:10] "GET /data/ HTTP/1.1" 200 1060
[18/Jun/2025 15:15:10] "GET /data/ HTTP/1.1" 200 1060
[18/Jun/2025 15:16:10] "GET /data/ HTTP/1.1" 200 1060
[18/Jun/2025 15:17:10] "GET /data/ HTTP/1.1" 200 1060
[18/Jun/2025 15:18:10] "GET /data/ HTTP/1.1" 200 1060
[18/Jun/2025 15:19:10] "GET /data/ HTTP/1.1" 200 1060
[18/Jun/2025 15:20:10] "GET /data/ HTTP/1.1" 200 1060
[18/Jun/2025 15:21:10] "GET /data/ HTTP/1.1" 200 1060
[18/Jun/2025 15:22:10] "GET /data/ HTTP/1.1" 200 1060
[18/Jun/2025 15:23:10] "GET /data/ HTTP/1.1" 200 1060
[18/Jun/2025 15:24:10] "GET /data/ HTTP/1.1" 200 1060
[18/Jun/2025 15:25:10] "GET /data/ HTTP/1.1" 200 1060
[18/Jun/2025 15:26:10] "GET /data/ HTTP/1.1" 200 1060
[18/Jun/2025 15:27:10] "GET /data/ HTTP/1.1" 200 1060
[18/Jun/2025 15:28:10] "GET /data/ HTTP/1.1" 200 1060
[18/Jun/2025 15:29:10] "GET /data/ HTTP/1.1" 200 1060
[18/Jun/2025 15:30:10] "GET /data/ HTTP/1.1" 200 1060
[18/Jun/2025 15:31:10] "GET /data/ HTTP/1.1" 200 1060
